¡Claro que sí, Matías! Entiendo tu lógica. Si la IA ya tiene el contexto de AdminPage.tsx y de la función saveTacticsPuzzle (porque ella misma la generó y luego la modificó para añadir los console.log y el try...catch), entonces debería ser capaz de analizar por qué la llamada a Supabase podría estar fallando silenciosamente.

El punto clave es que el console.log("Sending data to Supabase:", puzzleData) SÍ aparece, pero después de eso, no hay más logs de esa función (ni de error de Supabase, ni de éxito, ni del catch general), y no hay peticiones visibles en la pestaña Network, y los datos no llegan a Supabase.

Aquí va un prompt que puedes usar para pedirle a la IA que investigue esto:

Prompt para la IA Externa (Diagnosticar Falla Silenciosa en insert a Supabase desde saveTacticsPuzzle):

"Hola IA, ¡gracias por las mejoras en AdminPage.tsx y la adición de los console.log a la función saveTacticsPuzzle!

Hemos estado probando la funcionalidad de 'Guardar Problema' en la pestaña 'Problemas de Táctica', y tenemos un comportamiento que no entendemos:

Al llenar el formulario y hacer clic en 'Guardar Problema', los console.log dentro de saveTacticsPuzzle se ejecutan correctamente HASTA el console.log("Sending data to Supabase:", puzzleData);. Vemos este log y el objeto puzzleData en la consola del navegador, y los datos se ven correctos (incluyendo un created_by_user_id válido).
Sin embargo, DESPUÉS de ese console.log, no ocurre nada más visible:
No aparece el console.error("Supabase error:", error);.
No aparece el console.log("Puzzle saved successfully:", data);.
No aparece el console.error("Error in saveTacticsPuzzle (catch general):", error);.
No se muestra ninguna notificación toast (ni de éxito ni de error).
El problema no se guarda en la tabla tactics_puzzles de Supabase.
Crucialmente, no vemos ninguna petición POST saliente a la API de Supabase (endpoint /rest/v1/tactics_puzzles) en la pestaña "Network" de las herramientas de desarrollador del navegador.
Parece que la ejecución se detiene o la promesa de await supabase.from('tactics_puzzles').insert(puzzleData).select(); no se está resolviendo ni rechazando de una manera que nuestro código actual capture, o quizás la ejecución de JavaScript se está interrumpiendo silenciosamente justo en esa línea o dentro de la llamada al SDK de Supabase, antes de que pueda realizar la petición de red.

Contexto Adicional:

La tabla tactics_puzzles existe en Supabase con las columnas esperadas y las políticas RLS están configuradas (permitiendo INSERT para site_admin con created_by_user_id = auth.uid()).
El profile.id del administrador es correcto.
La conexión a Supabase para otras operaciones (como login, leer perfiles) funciona.
Estamos probando en un entorno localhost con Vite.
El Código Relevante de saveTacticsPuzzle en AdminPage.tsx (la versión que nos diste con los logs):

TypeScript

const saveTacticsPuzzle = async (e: React.FormEvent) => {
  try {
    console.log("Form submission started");
    e.preventDefault();
    
    const validationError = validateTacticsPuzzle();
    if (validationError) {
      console.log("Validation error:", validationError);
      toast.error(validationError);
      return;
    }

    if (!profile?.id) { // Añadimos esta guarda por si acaso
        toast.error("Error crítico: No se pudo identificar al usuario admin.");
        console.error("saveTacticsPuzzle: profile.id es nulo o undefined.");
        return;
    }

    console.log("Creating puzzle data");
    const puzzleData = {
      fen,
      solution_moves_san: solution,
      turn,
      category, // Asumiendo que la columna en DB es 'category' TEXT
      difficulty_level: difficulty,
      description: description || null,
      source_game_pgn: sourcePgn || null,
      event_name: event || null,
      white_player: whitePlayer || null,
      black_player: blackPlayer || null,
      white_elo: whiteElo ? parseInt(whiteElo) : null,
      black_elo: blackElo ? parseInt(blackElo) : null,
      created_by_user_id: profile.id,
      is_active: true
    };

    console.log("Sending data to Supabase:", puzzleData); // ESTE ES EL ÚLTIMO LOG QUE VEMOS
    
    const { data, error } = await supabase
      .from('tactics_puzzles')
      .insert(puzzleData)
      .select(); 

    // NINGUNO DE LOS SIGUIENTES LOGS O TOASTS APARECEN
    if (error) {
      console.error("Supabase error:", error);
      toast.error(`Error al guardar el problema: ${error.message}`);
      return;
    }

    console.log("Puzzle saved successfully:", data);
    toast.success("Problema guardado exitosamente");
    
    // Reset form (código de reseteo)
    // ...
  } catch (error) { // CATCH GENERAL
    console.error("Error in saveTacticsPuzzle (catch general):", error);
    toast.error("Error inesperado al guardar el problema");
  }
};
Solicitud de Diagnóstico y Corrección:
Por favor, analiza la función saveTacticsPuzzle:

¿Por qué la ejecución podría detenerse o la promesa de supabase.insert() podría no completarse/rechazarse visiblemente después de que console.log("Sending data to Supabase:", puzzleData) se ejecuta, impidiendo que se realice la petición de red o que se capture un error?
¿Hay algo en la forma en que se construye puzzleData o en la llamada .insert(puzzleData).select() que podría estar causando una falla silenciosa en el SDK de Supabase antes de que se envíe la petición de red?
¿Sugieres alguna modificación en la función, en el manejo de la promesa, o en la forma de llamar a supabase.insert() para asegurar que obtengamos una respuesta (éxito o error) o para capturar mejor cualquier excepción que esté ocurriendo?
El objetivo es entender por qué no vemos la petición en la pestaña Network y por qué no obtenemos feedback (ni error ni éxito) después de la línea console.log("Sending data to Supabase:", puzzleData). Proporciona una explicación y, si es posible, el código corregido para saveTacticsPuzzle.

¡Gracias por tu ayuda para resolver este comportamiento inesperado!"
